<?xml version="1.0" ?>
<!-- =================================================================================== -->
<!-- |    This document was autogenerated by xacro from arctos.urdf.xacro              | -->
<!-- |    EDITING THIS FILE BY HAND IS NOT RECOMMENDED                                 | -->
<!-- =================================================================================== -->
<robot name="arctos">
  <!-- Init colour -->
  <material name="black">
    <color rgba="0.0 0.0 0.0 1.0"/>
  </material>
  <material name="dark">
    <color rgba="0.3 0.3 0.3 1.0"/>
  </material>
  <material name="light_black">
    <color rgba="0.4 0.4 0.4 1.0"/>
  </material>
  <material name="blue">
    <color rgba="0.0 0.0 0.8 1.0"/>
  </material>
  <material name="green">
    <color rgba="0.0 0.8 0.0 1.0"/>
  </material>
  <material name="grey">
    <color rgba="0.5 0.5 0.5 1.0"/>
  </material>
  <material name="orange">
    <color rgba="1.0 0.4235294117647059 0.0392156862745098 1.0"/>
  </material>
  <material name="brown">
    <color rgba="0.8705882352941177 0.8117647058823529 0.7647058823529411 1.0"/>
  </material>
  <material name="red">
    <color rgba="0.8 0.0 0.0 1.0"/>
  </material>
  <material name="white">
    <color rgba="1.0 1.0 1.0 1.0"/>
  </material>
  <!-- <xacro:include filename="$(find arctos_description)/urdf/joint_link.xacro" /> -->
  <link name="Gripper_1">
    <visual>
      <origin rpy="0 0 0" xyz="0.0 0.323 -0.5685"/>
      <geometry>
        <mesh filename="package://arctos_description/meshes/Gripper_1.stl" scale="0.001 0.001 0.001"/>
      </geometry>
      <material name="white"/>
    </visual>
    <collision>
      <origin rpy="0 0 0" xyz="0.0 0.323 -0.5685"/>
      <geometry>
        <mesh filename="package://arctos_description/meshes/Gripper_1.stl" scale="0.001 0.001 0.001"/>
      </geometry>
    </collision>
    <inertial>
      <origin rpy="0 0 0" xyz="-0.001 -0.0211 0.0"/>
      <mass value="0.2"/>
      <inertia ixx="0.0001" ixy="-0.0" ixz="0.0" iyy="0.0001" iyz="0.0" izz="0.0001"/>
    </inertial>
  </link>
  <link name="Left_jaw_1">
    <visual>
      <origin rpy="0 0 0" xyz="0.0 0.323 -0.5685"/>
      <geometry>
        <mesh filename="package://arctos_description/meshes/Left_jaw_1.stl" scale="0.001 0.001 0.001"/>
      </geometry>
      <material name="white"/>
    </visual>
    <collision>
      <origin rpy="0 0 0" xyz="0.0 0.323 -0.5685"/>
      <geometry>
        <mesh filename="package://arctos_description/meshes/Left_jaw_1.stl" scale="0.001 0.001 0.001"/>
      </geometry>
    </collision>
    <inertial>
      <origin rpy="0 0 0" xyz="-0.0 -0.0211 0.0"/>
      <mass value="0.0"/>
      <inertia ixx="0.0" ixy="-0.0" ixz="0.0" iyy="0.0" iyz="0.0" izz="0.0"/>
    </inertial>
  </link>
  <link name="Right_jaw_1">
    <visual>
      <origin rpy="0 0 0" xyz="0.0 0.323 -0.5685"/>
      <geometry>
        <mesh filename="package://arctos_description/meshes/Right_jaw_1.stl" scale="0.001 0.001 0.001"/>
      </geometry>
      <material name="white"/>
    </visual>
    <collision>
      <origin rpy="0 0 0" xyz="0.0 0.323 -0.5685"/>
      <geometry>
        <mesh filename="package://arctos_description/meshes/Right_jaw_1.stl" scale="0.001 0.001 0.001"/>
      </geometry>
    </collision>
    <inertial>
      <origin rpy="0 0 0" xyz="-0.001 -0.0211 0.0"/>
      <mass value="0.0"/>
      <inertia ixx="0.0" ixy="-0.0" ixz="0.0" iyy="0.0" iyz="0.0" izz="0.0"/>
    </inertial>
  </link>
  <!-- Fixed gripper joint, no axis needed -->
  <!-- <xacro:arctos_joint
    name="Gripper_joint" type="fixed"
    parent="Link_6_1" child="Gripper_1"
    origin_xyz="0.0 -0.0 0.0" origin_rpy="0 0 0"
    limit_u="0.0" limit_l="0.0" limit_e="0.0" limit_v="0.0"
  /> -->
  <joint name="Left_jaw_joint" type="prismatic">
    <parent link="Gripper_1"/>
    <child link="Left_jaw_1"/>
    <origin rpy="0 0 0" xyz="0.0 0.0 0.0"/>
    <axis xyz="0 0 1"/>
    <limit effort="1.0" lower="0.0" upper="0.015" velocity="10.0"/>
  </joint>
  <joint name="Right_jaw_joint" type="prismatic">
    <parent link="Gripper_1"/>
    <child link="Right_jaw_1"/>
    <origin rpy="0 0 0" xyz="0.0 0.0 0.0"/>
    <axis xyz="0 0 1"/>
    <limit effort="1.0" lower="0.0" upper="0.015" velocity="10.0"/>
  </joint>
  <!-- Define all links -->
  <link name="world"/>
  <link name="tool_link"/>
  <link name="base_link">
    <visual>
      <origin rpy="0 0 0" xyz="0 0 0"/>
      <geometry>
        <mesh filename="package://arctos_description/meshes/base_link.stl" scale="0.001 0.001 0.001"/>
      </geometry>
      <material name="white"/>
    </visual>
    <collision>
      <origin rpy="0 0 0" xyz="0 0 0"/>
      <geometry>
        <mesh filename="package://arctos_description/meshes/base_link.stl" scale="0.001 0.001 0.001"/>
      </geometry>
    </collision>
    <inertial>
      <origin rpy="0 0 0" xyz="0.0009375030874740357 0.047087016508753216 0.06663230338123677"/>
      <mass value="2.3"/>
      <inertia ixx="0.0143" ixy="0.0" ixz="0.0" iyy="0.0055" iyz="0.0" izz="0.015"/>
    </inertial>
  </link>
  <link name="Link_1_1">
    <visual>
      <origin rpy="0 0 0" xyz="-0.0 -0.000 -0.1126"/>
      <geometry>
        <mesh filename="package://arctos_description/meshes/Link_1_1.stl" scale="0.001 0.001 0.001"/>
      </geometry>
      <material name="white"/>
    </visual>
    <collision>
      <origin rpy="0 0 0" xyz="-0.0 -0.000 -0.1126"/>
      <geometry>
        <mesh filename="package://arctos_description/meshes/Link_1_1.stl" scale="0.001 0.001 0.001"/>
      </geometry>
    </collision>
    <inertial>
      <origin rpy="0 0 0" xyz="-0.0088 -0.0005 0.099"/>
      <mass value="3.0396"/>
      <inertia ixx="0.0143" ixy="-0.0005657079999999999" ixz="-0.0016510779999999998" iyy="0.016218048" iyz="0.004233264" izz="0.008070888"/>
    </inertial>
  </link>
  <link name="Link_2_1">
    <visual>
      <origin rpy="0 0 0" xyz="0.0 0.020356 -0.2876"/>
      <geometry>
        <mesh filename="package://arctos_description/meshes/Link_2_1.stl" scale="0.001 0.001 0.001"/>
      </geometry>
      <material name="white"/>
    </visual>
    <collision>
      <origin rpy="0 0 0" xyz="0.0 0.020356 -0.2876"/>
      <geometry>
        <mesh filename="package://arctos_description/meshes/Link_2_1.stl" scale="0.001 0.001 0.001"/>
      </geometry>
    </collision>
    <inertial>
      <origin rpy="0 0 0" xyz="0.0042 0.010556 0.12979999999999997"/>
      <mass value="2.527"/>
      <inertia ixx="0.028157981999999998" ixy="0.001451172" ixz="-0.000511266" iyy="0.0299595" iyz="-0.0001773" izz="0.006298866"/>
    </inertial>
  </link>
  <link name="Link_3_1">
    <visual>
      <origin rpy="0 0 0" xyz="-0.0 0.019045 -0.54864"/>
      <geometry>
        <mesh filename="package://arctos_description/meshes/Link_3_1.stl" scale="0.001 0.001 0.001"/>
      </geometry>
      <material name="white"/>
    </visual>
    <collision>
      <origin rpy="0 0 0" xyz="-0.0 0.019045 -0.54864"/>
      <geometry>
        <mesh filename="package://arctos_description/meshes/Link_3_1.stl" scale="0.001 0.001 0.001"/>
      </geometry>
    </collision>
    <inertial>
      <origin rpy="0 0 0" xyz="0.00158 -0.053 0.009"/>
      <mass value="0.87"/>
      <inertia ixx="0.002798432" ixy="-6.1684e-05" ixz="7.019599999999999e-05" iyy="0.001082686" iyz="-0.00017481" izz="0.002657556"/>
    </inertial>
  </link>
  <link name="Link_4_1">
    <visual>
      <origin rpy="0 0 0" xyz="0.0 0.1578 -0.5704"/>
      <geometry>
        <mesh filename="package://arctos_description/meshes/Link_4_1.stl" scale="0.001 0.001 0.001"/>
      </geometry>
      <material name="white"/>
    </visual>
    <collision>
      <origin rpy="0 0 0" xyz="0.0 0.1578 -0.5704"/>
      <geometry>
        <mesh filename="package://arctos_description/meshes/Link_4_1.stl" scale="0.001 0.001 0.001"/>
      </geometry>
    </collision>
    <inertial>
      <origin rpy="0 0 0" xyz="0.0 -0.0535 -0.001733"/>
      <mass value="1.006"/>
      <inertia ixx="0.002094246" ixy="-0.0013240499999999998" ixz="8.1102e-05" iyy="0.0023952239999999996" iyz="1.9679999999999996e-06" izz="0.0031976"/>
    </inertial>
  </link>
  <link name="Link_5_1">
    <visual>
      <origin rpy="0 0 0" xyz="0.0 0.2832 -0.56856"/>
      <geometry>
        <mesh filename="package://arctos_description/meshes/Link_5_1.stl" scale="0.001 0.001 0.001"/>
      </geometry>
      <material name="white"/>
    </visual>
    <collision>
      <origin rpy="0 0 0" xyz="0.0 0.2832 -0.56856"/>
      <geometry>
        <mesh filename="package://arctos_description/meshes/Link_5_1.stl" scale="0.001 0.001 0.001"/>
      </geometry>
    </collision>
    <inertial>
      <origin rpy="0 0 0" xyz="-0.0007 -0.0142 -0.0008"/>
      <mass value="0.3344"/>
      <inertia ixx="0.0002" ixy="0.0" ixz="0.0" iyy="0.0005" iyz="0.0" izz="0.0005"/>
    </inertial>
  </link>
  <link name="Link_6_1">
    <visual>
      <origin rpy="0 0 0" xyz="0.0 0.323 -0.5685"/>
      <geometry>
        <mesh filename="package://arctos_description/meshes/Link_6_1.stl" scale="0.001 0.001 0.001"/>
      </geometry>
      <material name="white"/>
    </visual>
    <collision>
      <origin rpy="0 0 0" xyz="0.0 0.323 -0.5685"/>
      <geometry>
        <mesh filename="package://arctos_description/meshes/Link_6_1.stl" scale="0.001 0.001 0.001"/>
      </geometry>
    </collision>
    <inertial>
      <origin rpy="0.0 0.0 0.0" xyz="-0.0 -0.0 0.0"/>
      <mass value="0.001"/>
      <inertia ixx="0.001" ixy="-0.0" ixz="0.0" iyy="0.001" iyz="0.0" izz="0.001"/>
    </inertial>
  </link>
  <!-- Define all joints -->
  <joint name="base_joint" type="fixed">
    <parent link="world"/>
    <child link="base_link"/>
    <origin rpy="0 0 0" xyz="0 0 0"/>
    <axis xyz="0 0 1"/>
  </joint>
  <joint name="X_joint" type="continuous">
    <parent link="base_link"/>
    <child link="Link_1_1"/>
    <origin rpy="0 0 0" xyz="0.0 0.0 0.1126"/>
    <axis xyz="-0.0 0.0 1.0"/>
    <limit effort="24.3" lower="-3.141592653589793" upper="3.141592653589793" velocity="15.0"/>
  </joint>
  <joint name="Y_joint" type="continuous">
    <parent link="Link_1_1"/>
    <child link="Link_2_1"/>
    <origin rpy="0 0 0" xyz="0.0 -0.020356 0.17500000000000002"/>
    <axis xyz="1.0 -0.0 -0.0"/>
    <limit effort="270.0" lower="-0.96" upper="2.18" velocity="1.4"/>
  </joint>
  <joint name="Z_joint" type="continuous">
    <parent link="Link_2_1"/>
    <child link="Link_3_1"/>
    <origin rpy="0 0 0" xyz="0.0 0.001365 0.261035"/>
    <axis xyz="1.0 -0.0 0.0"/>
    <limit effort="97.0" lower="-1.5707963267948966" upper="1.2217304763960306" velocity="1.4"/>
  </joint>
  <joint name="A_joint" type="continuous">
    <parent link="Link_3_1"/>
    <child link="Link_4_1"/>
    <origin rpy="0 0 0" xyz="0 -0.13881 0.0217651"/>
    <axis xyz="-0.0 1.0 -0.0"/>
    <limit effort="22.0" lower="-3.141592653589793" upper="3.141592653589793" velocity="4.4"/>
  </joint>
  <joint name="B_joint" type="continuous">
    <parent link="Link_4_1"/>
    <child link="Link_5_1"/>
    <origin rpy="0 0 0" xyz="0.0 -0.12543 -0.00184"/>
    <axis xyz="-1.0 -0.0 0.0"/>
    <limit effort="16.0" lower="-1.55" upper="1.55" velocity="3.0"/>
  </joint>
  <joint name="C_joint" type="continuous">
    <parent link="Link_5_1"/>
    <child link="Link_6_1"/>
    <origin rpy="0 0 0" xyz="0.0 -0.0398 0.0"/>
    <axis xyz="-0.0 1.0 -0.0"/>
    <limit effort="16.0" lower="-3.141592653589793" upper="3.141592653589793" velocity="3.0"/>
  </joint>
  <joint name="hand_tool_joint" type="fixed">
    <parent link="Link_6_1"/>
    <child link="tool_link"/>
    <origin rpy="0 0 0" xyz="0.0 0.0 0.0"/>
  </joint>
  <!-- Activate Gazebo plugin -->
  <!-- <xacro:arctos_gazebo /> -->
  <!--- from moveit config package  -->
  <!-- <xacro:include filename="$(find arctos_description)/urdf/arctos.ros2_control.xacro" /> -->
  <!-- connection btw gripper and arm. Fixed gripper joint, no axis needed -->
  <joint name="gripper_base_joint" type="fixed">
    <parent link="tool_link"/>
    <child link="Gripper_1"/>
    <origin rpy="0 0 0" xyz="0.0 0.0 0.0"/>
  </joint>
  <ros2_control name="arm" type="system">
    <hardware>
      <plugin>mock_components/GenericSystem</plugin>
      <!-- <plugin>arctos_hardware_interface/ArctosHardwareInterface</plugin> -->
      <param name="can_interface">can0</param>
      <param name="accel">10</param>
      <param name="vel">100</param>
    </hardware>
    <joint name="X_joint">
      <param name="can_id">1</param>
      <param name="gear_ratio">13.5</param>
      <command_interface name="position"/>
      <state_interface name="position">
        <param name="initial_value">0.0</param>
      </state_interface>
      <state_interface name="velocity">
        <param name="initial_value">0.0</param>
      </state_interface>
      <!-- <state_interface name="effort">
        <param name="initial_value">0.0</param>
      </state_interface> -->
    </joint>
    <joint name="Y_joint">
      <param name="can_id">2</param>
      <param name="gear_ratio">150.0</param>
      <command_interface name="position"/>
      <state_interface name="position">
        <param name="initial_value">0.0</param>
      </state_interface>
      <state_interface name="velocity">
        <param name="initial_value">0.0</param>
      </state_interface>
      <!-- <state_interface name="effort">
        <param name="initial_value">0.0</param>
      </state_interface> -->
    </joint>
    <joint name="Z_joint">
      <param name="can_id">3</param>
      <param name="gear_ratio">150.0</param>
      <command_interface name="position"/>
      <state_interface name="position">
        <param name="initial_value">0.0</param>
      </state_interface>
      <state_interface name="velocity">
        <param name="initial_value">0.0</param>
      </state_interface>
      <!-- <state_interface name="effort">
        <param name="initial_value">0.0</param>
      </state_interface> -->
    </joint>
    <joint name="A_joint">
      <param name="can_id">4</param>
      <param name="gear_ratio">48.0</param>
      <command_interface name="position"/>
      <state_interface name="position">
        <param name="initial_value">0.0</param>
      </state_interface>
      <state_interface name="velocity">
        <param name="initial_value">0.0</param>
      </state_interface>
      <!-- <state_interface name="effort">
        <param name="initial_value">0.0</param>
      </state_interface> -->
    </joint>
    <joint name="B_joint">
      <param name="can_id">5</param>
      <param name="gear_ratio">67.82</param>
      <command_interface name="position"/>
      <state_interface name="position">
        <param name="initial_value">0.0</param>
      </state_interface>
      <state_interface name="velocity">
        <param name="initial_value">0.0</param>
      </state_interface>
      <!-- <state_interface name="effort">
        <param name="initial_value">0.0</param>
      </state_interface> -->
    </joint>
    <joint name="C_joint">
      <param name="can_id">6</param>
      <param name="gear_ratio">67.82</param>
      <command_interface name="position"/>
      <state_interface name="position">
        <param name="initial_value">0.0</param>
      </state_interface>
      <state_interface name="velocity">
        <param name="initial_value">0.0</param>
      </state_interface>
      <!-- <state_interface name="effort">
        <param name="initial_value">0.0</param>
      </state_interface> -->
    </joint>
  </ros2_control>
  <ros2_control name="gripper" type="system">
    <hardware>
      <plugin>mock_components/GenericSystem</plugin>
    </hardware>
    <joint name="Right_jaw_joint">
      <command_interface name="position"/>
      <state_interface name="position">
        <param name="initial_value">0.0</param>
      </state_interface>
    </joint>
  </ros2_control>
  <!-- ros2_control with mock components is included directly from arctos.ros2_control.xacro -->
  <!-- include gazebo parameters -->
  <!-- <xacro:include filename="$(find arctos_description)/urdf/smallrobot_gazebo.xacro" /> -->
</robot>
